Fix whatever is wrong with my Model
    ERROR:Traceback (most recent call last):
        File "C:\Users\rjcou\Documents\DevMtn\Specs_Capstone\env\Lib\site-packages\sqlalchemy\sql\schema.py", line 224, in _init_items
            spwd = item._set_parent_with_dispatch
                ^^^^^^^^^^^^^^^^^^^^^^^^^^^^^^
        File "C:\Users\rjcou\Documents\DevMtn\Specs_Capstone\env\Lib\site-packages\sqlalchemy\util\langhelpers.py", line 1327, in __getattr__
            return self._fallback_getattr(key)
                ^^^^^^^^^^^^^^^^^^^^^^^^^^^
        File "C:\Users\rjcou\Documents\DevMtn\Specs_Capstone\env\Lib\site-packages\sqlalchemy\util\langhelpers.py", line 1296, in _fallback_getattr
            raise AttributeError(key)
        AttributeError: _set_parent_with_dispatch

        The above exception was the direct cause of the following exception:

        Traceback (most recent call last):
        File "c:\Users\rjcou\Documents\DevMtn\Specs_Capstone\seed.py", line 2, in <module>
            import model
        File "c:\Users\rjcou\Documents\DevMtn\Specs_Capstone\model.py", line 36, in <module>
            class Task(db.Model):
        File "c:\Users\rjcou\Documents\DevMtn\Specs_Capstone\model.py", line 44, in Task
            project_id=db.Column(db.Integer, db.relationship("projects.project.id"), nullable=False)
                    ^^^^^^^^^^^^^^^^^^^^^^^^^^^^^^^^^^^^^^^^^^^^^^^^^^^^^^^^^^^^^^^^^^^^^^^^^^^^^
        File "C:\Users\rjcou\Documents\DevMtn\Specs_Capstone\env\Lib\site-packages\sqlalchemy\sql\schema.py", line 2150, in __init__
            self._init_items(*cast(_typing_Sequence[SchemaItem], l_args))
        File "C:\Users\rjcou\Documents\DevMtn\Specs_Capstone\env\Lib\site-packages\sqlalchemy\sql\schema.py", line 226, in _init_items
            raise exc.ArgumentError(
        sqlalchemy.exc.ArgumentError: 'SchemaItem' object, such as a 'Column' or a 'Constraint' expected, got <Relationship at 0x22b417a2670; no key>
                
